<?xml version="1.0"?>
<robot xmlns:xacro="http://www.ros.org/wiki/xacro"  name="robot">

    <xacro:include filename="materials.xacro"/>
    <xacro:include filename="inertial_macros.xacro"/>
    
    
    
    <!-- BASE LINK -->
    
    <link name="base_link">  
    </link>
    
    <joint name="base_footprint_joint" type="fixed">
        <parent link="base_link"/>
        <child link="base_footprint"/>
        <origin xyz="0 0 0" rpy="0 0 0"/>
    </joint>

    <link name="base_footprint">
    </link>

    <!-- IMU LINK -->

    <joint name="imu_joint" type="fixed">
        <parent link="base_link"/>
        <child link="imu_link"/>
        <origin xyz="0 0 0.075"/>
    </joint>	
    
    <link name="imu_link">
        <visual>
          <geometry>
            <box size="0.1 0.1 0.1"/>
          </geometry>
        </visual>
      
        <collision>
          <geometry>
            <box size="0.1 0.1 0.1"/>
          </geometry>
        </collision>

        <xacro:inertial_box mass="0.1" x="0.1" y="0.1" z="0.1">
          <origin xyz="0. 0 0.0" rpy="0 0 0"/>
        </xacro:inertial_box>
    </link>
    
    <gazebo reference="imu_link">
        <gravity>true</gravity> 
        <sensor name="imu_sensor" type="imu">
         <plugin filename="libgazebo_ros_imu_sensor.so" name="imu_plugin">
            <ros>
              <!-- <namespace>odometry</namespace> -->
              <remapping>~/out:=imu</remapping>
            </ros>
            <initial_orientation_as_reference>true</initial_orientation_as_reference>
          </plugin>
          <always_on>true</always_on>
          <update_rate>150</update_rate>
          <visualize>true</visualize>
          <imu>
            <angular_velocity>
              <x>
                <noise type="gaussian">
                  <mean>0.0</mean>
                  <stddev>2e-4</stddev>
                  <bias_mean>0.0000075</bias_mean>
                  <bias_stddev>0.0000008</bias_stddev>
                </noise>
              </x>
              <y>
                <noise type="gaussian">
                  <mean>0.0</mean>
                  <stddev>2e-4</stddev>
                  <bias_mean>0.0000075</bias_mean>
                  <bias_stddev>0.0000008</bias_stddev>
                </noise>
              </y>
              <z>
                <noise type="gaussian">
                  <mean>0.0</mean>
                  <stddev>2e-4</stddev>
                  <bias_mean>0.0000075</bias_mean>
                  <bias_stddev>0.0000008</bias_stddev>
                </noise>
              </z>
            </angular_velocity>
            <linear_acceleration>
              <x>
                <noise type="gaussian">
                  <mean>0.0</mean>
                  <stddev>1.7e-2</stddev>
                  <bias_mean>0.1</bias_mean>
                  <bias_stddev>0.001</bias_stddev>
                </noise>
              </x>
              <y>
                <noise type="gaussian">
                  <mean>0.0</mean>
                  <stddev>1.7e-2</stddev>
                  <bias_mean>0.1</bias_mean>
                  <bias_stddev>0.001</bias_stddev>
                </noise>
              </y>
              <z>
                <noise type="gaussian">
                  <mean>0.0</mean>
                  <stddev>1.7e-2</stddev>
                  <bias_mean>0.1</bias_mean>
                  <bias_stddev>0.001</bias_stddev>
                </noise>
              </z>
            </linear_acceleration>
          </imu>
        </sensor>
    </gazebo>


    <!-- CHASSIS LINK -->

    <joint name="chassis_joint" type="fixed">
        <parent link="base_link"/>
        <child link="chassis"/>
        <origin xyz="-0.1 0 0"/>
    </joint>

    <link name="chassis">
        <visual>
            <origin xyz="0.15 0 0.075"/>
            <geometry>
                <box size="0.3 0.3 0.15"/>
            </geometry>
            <material name="orange"/>
        </visual>
        <collision>
            <origin xyz="0.15 0 0.075"/>
            <geometry>
                <box size="0.3 0.3 0.15"/>
            </geometry>
        </collision>
        <xacro:inertial_box mass="0.5" x="0.3" y="0.3" z="0.15">
            <origin xyz="0.15 0 0.075" rpy="0 0 0"/>
        </xacro:inertial_box>
    </link>

    <gazebo reference="chassis">
        <material>Gazebo/Orange</material>
    </gazebo>


    
    <!-- LEFT WHEEL LINK -->

    <joint name="left_wheel_joint" type="continuous">
        <parent link="base_link"/>
        <child link="left_wheel"/>
        <origin xyz="0 0.175 0" rpy="-${pi/2} 0 0" />
        <axis xyz="0 0 1"/>
    </joint>

    <link name="left_wheel">
        <visual>
            <geometry>
                <cylinder radius="0.05" length="0.04"/>
            </geometry>
            <material name="black"/>
        </visual>
        <collision>
            <geometry>
                <cylinder radius="0.05" length="0.04"/>
            </geometry>
        </collision>
        <xacro:inertial_cylinder mass="0.1" length="0.04" radius="0.05">
            <origin xyz="0 0 0" rpy="0 0 0"/>
        </xacro:inertial_cylinder>
    </link>


    <gazebo reference="left_wheel">
        <material>Gazebo/Black</material>
    </gazebo>


    <!-- RIGHT WHEEL LINK -->

    <joint name="right_wheel_joint" type="continuous">
        <parent link="base_link"/>
        <child link="right_wheel"/>
        <origin xyz="0 -0.175 0" rpy="${pi/2} 0 0" />
        <axis xyz="0 0 -1"/>
    </joint>

    <link name="right_wheel">
        <visual>
            <geometry>
                <cylinder radius="0.05" length="0.04"/>
            </geometry>
            <material name="black"/>
        </visual>
        <collision>
            <geometry>
                <cylinder radius="0.05" length="0.04"/>
            </geometry>
        </collision>
        <xacro:inertial_cylinder mass="0.1" length="0.04" radius="0.05">
            <origin xyz="0 0 0" rpy="0 0 0"/>
        </xacro:inertial_cylinder>
    </link>


    <gazebo reference="right_wheel">
        <material>Gazebo/Black</material>
    </gazebo>


    <!-- CASTER WHEEL LINK -->

    <joint name="caster_wheel_joint" type="fixed">
        <parent link="chassis"/>
        <child link="caster_wheel"/>
        <origin xyz="0.24 0 0"/>
    </joint>


    <link name="caster_wheel">
        <visual>
            <geometry>
                <sphere radius="0.05"/>
            </geometry>
            <material name="black"/>
        </visual>
        <collision>
            <geometry>
                <sphere radius="0.05"/>
            </geometry>
        </collision>
        <xacro:inertial_sphere mass="0.1" radius="0.05">
            <origin xyz="0 0 0" rpy="0 0 0"/>
        </xacro:inertial_sphere>
    </link>

    
    <gazebo reference="caster_wheel">
        <material>Gazebo/Black</material>
        <mu1 value="0.001 "/>
        <mu2 value="0.001"/>
    </gazebo>

</robot>